<?xml version="1.0" encoding="utf-8"?>
<!-- This URDF was automatically created by SolidWorks to URDF Exporter! Originally created by Stephen Brawner (brawner@gmail.com) 
     Commit Version: 1.5.1-0-g916b5db  Build Version: 1.5.7152.31018
     For more information, please see http://wiki.ros.org/sw_urdf_exporter -->
<robot xmlns:xacro="http://www.ros.org/wiki/xacro" 
  name="MarsRover">
  <xacro:include filename="$(find mars_rover)/urdf/MarsRover.gazebo" />
  <xacro:property name="PI" value="3.141592654" />
  <xacro:property name="LidarAngle" value="${PI/180*0}" />
  <xacro:property name="LidarHeight" value="-0.0" />
  <xacro:property name="LidarName" value="PandarQT" />
  <xacro:property name="LidarDataTopicName" value="PandarQT_Data" />
  <xacro:property name="LidarHz" value="10" />
  <xacro:property name="LidarLasers" value="64" />
  <xacro:property name="LidarSamples" value="600" />
  <xacro:property name="LidarBeamVisual" value="false" />

  <link
    name="body">
    <inertial>
      <origin
        xyz="-0.0001479 -1.1102E-16 -0.38223"
        rpy="0 0 0" />
      <mass
        value="32.929" />
      <inertia
        ixx="4.4749"
        ixy="-1.3173E-14"
        ixz="-0.00050348"
        iyy="7.3974"
        iyz="-8.0126E-16"
        izz="9.2942" />
    </inertial>
    <visual>
      <origin
        xyz="0 0 0"
        rpy="0 0 0" />
      <geometry>
        <mesh
          filename="package://mars_rover/meshes/body.dae" />
      </geometry>
      <material
        name="">
        <color
          rgba="0.75294 0.75294 0.75294 1" />
      </material>
    </visual>
    <collision>
      <origin
        xyz="0 0 0"
        rpy="0 0 0" />
      <geometry>
        <mesh
          filename="package://mars_rover/meshes/body.dae" />
      </geometry>
    </collision>
  </link>
  <link
    name="DiffBar">
    <inertial>
      <origin
        xyz="7.2337E-10 -3.373E-08 -0.022313"
        rpy="0 0 0" />
      <mass
        value="1.4917" />
      <inertia
        ixx="0.030386"
        ixy="-6.0053E-07"
        ixz="-4.2736E-11"
        iyy="0.00058396"
        iyz="-1.8798E-08"
        izz="0.030095" />
    </inertial>
    <visual>
      <origin
        xyz="0 0 0"
        rpy="0 0 0" />
      <geometry>
        <mesh
          filename="package://mars_rover/meshes/DiffBar.dae" />
      </geometry>
      <material
        name="">
        <color
          rgba="0.89804 0.91765 0.92941 1" />
      </material>
    </visual>
    <collision>
      <origin
        xyz="0 0 0"
        rpy="0 0 0" />
      <geometry>
        <mesh
          filename="package://mars_rover/meshes/DiffBar.dae" />
      </geometry>
    </collision>
  </link>
  <joint
    name="joint_body_DiffBar"
    type="continuous">
    <origin
      xyz="0.20043 0 -0.525"
      rpy="0 0 0" />
    <parent
      link="body" />
    <child
      link="DiffBar" />
    <axis
      xyz="0 0 1" />
  </joint>
  <link
    name="LeftMainRocket">
    <inertial>
      <origin
        xyz="0.19478 0.032219 -0.10164"
        rpy="0 0 0" />
      <mass
        value="2.3166" />
      <inertia
        ixx="0.025318"
        ixy="-0.0056299"
        ixz="0.076395"
        iyy="0.32297"
        iyz="0.0021277"
        izz="0.30151" />
    </inertial>
    <visual>
      <origin
        xyz="0 0 0"
        rpy="0 0 0" />
      <geometry>
        <mesh
          filename="package://mars_rover/meshes/LeftMainRocket.dae" />
      </geometry>
      <material
        name="">
        <color
          rgba="0.79216 0.81961 0.93333 1" />
      </material>
    </visual>
    <collision>
      <origin
        xyz="0 0 0"
        rpy="0 0 0" />
      <geometry>
        <mesh
          filename="package://mars_rover/meshes/LeftMainRocket.dae" />
      </geometry>
    </collision>
  </link>
  <joint
    name="joint_body_LeftMainRocket"
    type="continuous">
    <origin
      xyz="0 0.395 -0.455"
      rpy="0 0 0" />
    <parent
      link="body" />
    <child
      link="LeftMainRocket" />
    <axis
      xyz="0 -1 0" />
  </joint>
  <link
    name="LeftViceRocket">
    <inertial>
      <origin
        xyz="0.00032494 0.0045778 -0.14283"
        rpy="0 0 0" />
      <mass
        value="1.7019" />
      <inertia
        ixx="0.011641"
        ixy="-1.7935E-06"
        ixz="-0.00023484"
        iyy="0.12548"
        iyz="0.00078835"
        izz="0.11487" />
    </inertial>
    <visual>
      <origin
        xyz="0 0 0"
        rpy="0 0 0" />
      <geometry>
        <mesh
          filename="package://mars_rover/meshes/LeftViceRocket.dae" />
      </geometry>
      <material
        name="">
        <color
          rgba="0.79216 0.81961 0.93333 1" />
      </material>
    </visual>
    <collision>
      <origin
        xyz="0 0 0"
        rpy="0 0 0" />
      <geometry>
        <mesh
          filename="package://mars_rover/meshes/LeftViceRocket.dae" />
      </geometry>
    </collision>
  </link>
  <joint
    name="joint_LeftMainRocket_LeftViceRocket"
    type="continuous">
    <origin
      xyz="-0.40088 0.055 -0.023072"
      rpy="0 0 0" />
    <parent
      link="LeftMainRocket" />
    <child
      link="LeftViceRocket" />
    <axis
      xyz="0 -1 0" />
  </joint>
  <link
    name="LeftMiddleWheel">
    <inertial>
      <origin
        xyz="0 -1.6653E-16 -2.7756E-17"
        rpy="0 0 0" />
      <mass
        value="2.468" />
      <inertia
        ixx="0.021876"
        ixy="8.5663E-19"
        ixz="-1.1926E-17"
        iyy="0.040526"
        iyz="-4.7148E-18"
        izz="0.021876" />
    </inertial>
    <visual>
      <origin
        xyz="0 0 0"
        rpy="0 0 0" />
      <geometry>
        <mesh
          filename="package://mars_rover/meshes/LeftMiddleWheel.dae" />
      </geometry>
      <material
        name="">
        <color
          rgba="0.79216 0.81961 0.93333 1" />
      </material>
    </visual>
    <collision>
      <origin
        xyz="0 0 0"
        rpy="0 0 0" />
      <geometry>
        <mesh
          filename="package://mars_rover/meshes/LeftMiddleWheel.dae" />
      </geometry>
    </collision>
  </link>
  <joint
    name="joint_LeftViceRocket_LeftMiddleWheel"
    type="continuous">
    <origin
      xyz="0.38804 0.09 -0.24313"
      rpy="0 0 0" />
    <parent
      link="LeftViceRocket" />
    <child
      link="LeftMiddleWheel" />
    <axis
      xyz="0 1 0" />
  </joint>
  <link
    name="LeftRearWheel">
    <inertial>
      <origin
        xyz="-5.5511E-17 -5.5511E-17 0"
        rpy="0 0 0" />
      <mass
        value="2.468" />
      <inertia
        ixx="0.021876"
        ixy="2.3544E-18"
        ixz="-1.088E-17"
        iyy="0.040526"
        iyz="-3.3563E-18"
        izz="0.021876" />
    </inertial>
    <visual>
      <origin
        xyz="0 0 0"
        rpy="0 0 0" />
      <geometry>
        <mesh
          filename="package://mars_rover/meshes/LeftRearWheel.dae" />
      </geometry>
      <material
        name="">
        <color
          rgba="0.79216 0.81961 0.93333 1" />
      </material>
    </visual>
    <collision>
      <origin
        xyz="0 0 0"
        rpy="0 0 0" />
      <geometry>
        <mesh
          filename="package://mars_rover/meshes/LeftRearWheel.dae" />
      </geometry>
    </collision>
  </link>
  <joint
    name="joint_LeftViceRocket_LeftRearWheel"
    type="continuous">
    <origin
      xyz="-0.38693 0.09 -0.2449"
      rpy="0 0 0" />
    <parent
      link="LeftViceRocket" />
    <child
      link="LeftRearWheel" />
    <axis
      xyz="0 1 0" />
  </joint>
  <link
    name="LeftFrontWheel">
    <inertial>
      <origin
        xyz="0 0 8.3267E-17"
        rpy="0 0 0" />
      <mass
        value="2.468" />
      <inertia
        ixx="0.021876"
        ixy="-1.137E-18"
        ixz="1.0907E-17"
        iyy="0.040526"
        iyz="-4.2082E-18"
        izz="0.021876" />
    </inertial>
    <visual>
      <origin
        xyz="0 0 0"
        rpy="0 0 0" />
      <geometry>
        <mesh
          filename="package://mars_rover/meshes/LeftFrontWheel.dae" />
      </geometry>
      <material
        name="">
        <color
          rgba="0.79216 0.81961 0.93333 1" />
      </material>
    </visual>
    <collision>
      <origin
        xyz="0 0 0"
        rpy="0 0 0" />
      <geometry>
        <mesh
          filename="package://mars_rover/meshes/LeftFrontWheel.dae" />
      </geometry>
    </collision>
  </link>
  <joint
    name="joint_LeftMainRocket_LeftFrontWheel"
    type="continuous">
    <origin
      xyz="0.75893 0.145 -0.27932"
      rpy="0 0 0" />
    <parent
      link="LeftMainRocket" />
    <child
      link="LeftFrontWheel" />
    <axis
      xyz="0 1 0" />
  </joint>
  <!-- <link
    name="LeftDiffBarLink">
    <inertial>
      <origin
        xyz="0.10084 -3.0748E-11 0"
        rpy="0 0 0" />
      <mass
        value="0.20075" />
      <inertia
        ixx="1.7094E-05"
        ixy="4.2541E-13"
        ixz="4.7701E-20"
        iyy="0.0014123"
        iyz="-1.7457E-10"
        izz="0.0014123" />
    </inertial>
    <visual>
      <origin
        xyz="0 0 0"
        rpy="0 0 0" />
      <geometry>
        <mesh
          filename="package://mars_rover/meshes/LeftDiffBarLink.dae" />
      </geometry>
      <material
        name="">
        <color
          rgba="0.89804 0.91765 0.92941 1" />
      </material>
    </visual>
    <collision>
      <origin
        xyz="0 0 0"
        rpy="0 0 0" />
      <geometry>
        <mesh
          filename="package://mars_rover/meshes/LeftDiffBarLink.dae" />
      </geometry>
    </collision>
  </link>
  <joint
    name="joint_LeftMainRocket_DiffBarLink"
    type="continuous">
    <origin
      xyz="-0.00040847 -0.095 -0.084999"
      rpy="0 0 0" />
    <parent
      link="LeftMainRocket" />
    <child
      link="LeftDiffBarLink" />
    <axis
      xyz="1 0 0" />
  </joint> -->
  <link
    name="RightMainRocket">
    <inertial>
      <origin
        xyz="0.19476 -0.032219 -0.10167"
        rpy="0 0 0" />
      <mass
        value="2.3166" />
      <inertia
        ixx="0.02534"
        ixy="0.0056295"
        ixz="0.076435"
        iyy="0.32297"
        iyz="-0.0021285"
        izz="0.30149" />
    </inertial>
    <visual>
      <origin
        xyz="0 0 0"
        rpy="0 0 0" />
      <geometry>
        <mesh
          filename="package://mars_rover/meshes/RightMainRocket.dae" />
      </geometry>
      <material
        name="">
        <color
          rgba="0.79216 0.81961 0.93333 1" />
      </material>
    </visual>
    <collision>
      <origin
        xyz="0 0 0"
        rpy="0 0 0" />
      <geometry>
        <mesh
          filename="package://mars_rover/meshes/RightMainRocket.dae" />
      </geometry>
    </collision>
  </link>
  <joint
    name="joint_body_RightMainRocket"
    type="continuous">
    <origin
      xyz="0 -0.395 -0.455"
      rpy="0 0 0" />
    <parent
      link="body" />
    <child
      link="RightMainRocket" />
    <axis
      xyz="0 1 0" />
  </joint>
  <link
    name="RightViceRocket">
    <inertial>
      <origin
        xyz="-3.7473E-05 -0.0045778 -0.14283"
        rpy="0 0 0" />
      <mass
        value="1.7019" />
      <inertia
        ixx="0.01164"
        ixy="-2.0683E-07"
        ixz="2.7083E-05"
        iyy="0.12548"
        iyz="-0.00078835"
        izz="0.11487" />
    </inertial>
    <visual>
      <origin
        xyz="0 0 0"
        rpy="0 0 0" />
      <geometry>
        <mesh
          filename="package://mars_rover/meshes/RightViceRocket.dae" />
      </geometry>
      <material
        name="">
        <color
          rgba="0.79216 0.81961 0.93333 1" />
      </material>
    </visual>
    <collision>
      <origin
        xyz="0 0 0"
        rpy="0 0 0" />
      <geometry>
        <mesh
          filename="package://mars_rover/meshes/RightViceRocket.dae" />
      </geometry>
    </collision>
  </link>
  <joint
    name="joint_RightMainRocket_RightViceRocket"
    type="continuous">
    <origin
      xyz="-0.40088 -0.055 -0.023015"
      rpy="0 0 0" />
    <parent
      link="RightMainRocket" />
    <child
      link="RightViceRocket" />
    <axis
      xyz="0 -1 0" />
  </joint>
  <link
    name="RightMiddleWheel">
    <inertial>
      <origin
        xyz="5.5511E-17 -4.4409E-16 2.7756E-17"
        rpy="0 0 0" />
      <mass
        value="2.468" />
      <inertia
        ixx="0.021876"
        ixy="5.6669E-19"
        ixz="-1.8696E-18"
        iyy="0.040526"
        iyz="7.0045E-19"
        izz="0.021876" />
    </inertial>
    <visual>
      <origin
        xyz="0 0 0"
        rpy="0 0 0" />
      <geometry>
        <mesh
          filename="package://mars_rover/meshes/RightMiddleWheel.dae" />
      </geometry>
      <material
        name="">
        <color
          rgba="0.79216 0.81961 0.93333 1" />
      </material>
    </visual>
    <collision>
      <origin
        xyz="0 0 0"
        rpy="0 0 0" />
      <geometry>
        <mesh
          filename="package://mars_rover/meshes/RightMiddleWheel.dae" />
      </geometry>
    </collision>
  </link>
  <joint
    name="joint_RightViceRocket_RightMiddleWheel"
    type="continuous">
    <origin
      xyz="0.38742 -0.09 -0.24412"
      rpy="0 0 0" />
    <parent
      link="RightViceRocket" />
    <child
      link="RightMiddleWheel" />
    <axis
      xyz="0 -1 0" />
  </joint>
  <link
    name="RightRearWheel">
    <inertial>
      <origin
        xyz="-5.5511E-17 -2.2204E-16 0"
        rpy="0 0 0" />
      <mass
        value="2.468" />
      <inertia
        ixx="0.021876"
        ixy="2.2071E-18"
        ixz="-8.4262E-18"
        iyy="0.040526"
        iyz="5.2919E-19"
        izz="0.021876" />
    </inertial>
    <visual>
      <origin
        xyz="0 0 0"
        rpy="0 0 0" />
      <geometry>
        <mesh
          filename="package://mars_rover/meshes/RightRearWheel.dae" />
      </geometry>
      <material
        name="">
        <color
          rgba="0.79216 0.81961 0.93333 1" />
      </material>
    </visual>
    <collision>
      <origin
        xyz="0 0 0"
        rpy="0 0 0" />
      <geometry>
        <mesh
          filename="package://mars_rover/meshes/RightRearWheel.dae" />
      </geometry>
    </collision>
  </link>
  <joint
    name="joint_RightViceRocket_RightRearWheel"
    type="continuous">
    <origin
      xyz="-0.38755 -0.09 -0.24391"
      rpy="0 0 0" />
    <parent
      link="RightViceRocket" />
    <child
      link="RightRearWheel" />
    <axis
      xyz="0 -1 0" />
  </joint>
  <link
    name="RightFrontWheel">
    <inertial>
      <origin
        xyz="2.2204E-16 -2.2204E-16 2.7756E-17"
        rpy="0 0 0" />
      <mass
        value="2.468" />
      <inertia
        ixx="0.021876"
        ixy="7.7604E-19"
        ixz="-2.648E-18"
        iyy="0.040526"
        iyz="-6.0073E-18"
        izz="0.021876" />
    </inertial>
    <visual>
      <origin
        xyz="0 0 0"
        rpy="0 0 0" />
      <geometry>
        <mesh
          filename="package://mars_rover/meshes/RightFrontWheel.dae" />
      </geometry>
      <material
        name="">
        <color
          rgba="0.79216 0.81961 0.93333 1" />
      </material>
    </visual>
    <collision>
      <origin
        xyz="0 0 0"
        rpy="0 0 0" />
      <geometry>
        <mesh
          filename="package://mars_rover/meshes/RightFrontWheel.dae" />
      </geometry>
    </collision>
  </link>
  <joint
    name="joint_RightMainRocket_RightFrontWheel"
    type="continuous">
    <origin
      xyz="0.75889 -0.145 -0.27943"
      rpy="0 0 0" />
    <parent
      link="RightMainRocket" />
    <child
      link="RightFrontWheel" />
    <axis
      xyz="0 -1 0" />
  </joint>
  <!-- <link
    name="RightDiffBarLink">
    <inertial>
      <origin
        xyz="0.10084 3.0748E-11 -5.5511E-17"
        rpy="0 0 0" />
      <mass
        value="0.20075" />
      <inertia
        ixx="1.7094E-05"
        ixy="-4.2541E-13"
        ixz="3.1651E-20"
        iyy="0.0014123"
        iyz="2.614E-10"
        izz="0.0014123" />
    </inertial>
    <visual>
      <origin
        xyz="0 0 0"
        rpy="0 0 0" />
      <geometry>
        <mesh
          filename="package://mars_rover/meshes/RightDiffBarLink.dae" />
      </geometry>
      <material
        name="">
        <color
          rgba="0.89804 0.91765 0.92941 1" />
      </material>
    </visual>
    <collision>
      <origin
        xyz="0 0 0"
        rpy="0 0 0" />
      <geometry>
        <mesh
          filename="package://mars_rover/meshes/RightDiffBarLink.dae" />
      </geometry>
    </collision>
  </link>
  <joint
    name="joint_RightMainRocket_DiffBarLink"
    type="continuous">
    <origin
      xyz="-0.00042056 0.095 -0.084999"
      rpy="0 0 0" />
    <parent
      link="RightMainRocket" />
    <child
      link="RightDiffBarLink" />
    <axis
      xyz="1 0 0" />
  </joint> -->
  <link
    name="LiDARBodyCon">
    <inertial>
      <origin
        xyz="-0.049583 -1.1102E-16 -0.01309"
        rpy="0 0 0" />
      <mass
        value="0.2293" />
      <inertia
        ixx="0.00036659"
        ixy="-5.8124E-20"
        ixz="-4.7613E-05"
        iyy="0.00023526"
        iyz="-2.3775E-20"
        izz="0.00053318" />
    </inertial>
    <visual>
      <origin
        xyz="0 0 0"
        rpy="0 0 0" />
      <geometry>
        <mesh
          filename="package://mars_rover/meshes/LiDARBodyCon.dae" />
      </geometry>
      <material
        name="">
        <color
          rgba="0.89804 0.91765 0.92941 1" />
      </material>
    </visual>
    <collision>
      <origin
        xyz="0 0 0"
        rpy="0 0 0" />
      <geometry>
        <mesh
          filename="package://mars_rover/meshes/LiDARBodyCon.dae" />
      </geometry>
    </collision>
  </link>
  <joint
    name="joint_body_LiDARCon"
    type="fixed">
    <origin
      xyz="0.6825 0 0.004"
      rpy="0 0 0" />
    <parent
      link="body" />
    <child
      link="LiDARBodyCon" />
    <axis
      xyz="0 0 0" />
  </joint>
  <link
    name="LiDARSupport">
    <inertial>
      <origin
        xyz="-0.016892 0 0.036225"
        rpy="0 0 0" />
      <mass
        value="0.23629" />
      <inertia
        ixx="0.00044478"
        ixy="-4.1152E-20"
        ixz="5.4657E-05"
        iyy="0.00014519"
        iyz="5.8651E-20"
        izz="0.00035306" />
    </inertial>
    <visual>
      <origin
        xyz="0 0 0"
        rpy="0 0 0" />
      <geometry>
        <mesh
          filename="package://mars_rover/meshes/LiDARSupport.dae" />
      </geometry>
      <material
        name="">
        <color
          rgba="0.89804 0.91765 0.92941 1" />
      </material>
    </visual>
    <collision>
      <origin
        xyz="0 0 0"
        rpy="0 0 0" />
      <geometry>
        <mesh
          filename="package://mars_rover/meshes/LiDARSupport.dae" />
      </geometry>
    </collision>
  </link>
  <joint
    name="joint_LiDARBodyCon_LiDARSupport"
    type="fixed">
    <origin
      xyz="0 0 0"
      rpy="0 ${LidarAngle} 0" />
    <parent
      link="LiDARBodyCon" />
    <child
      link="LiDARSupport" />
    <axis
      xyz="0 1 0" />
    <limit
      lower="0"
      upper="0"
      effort="0"
      velocity="0" />
  </joint>
  <link
    name="LiDAR">
    <inertial>
      <origin
        xyz="-0.00012666 -9.4209E-09 -0.012924"
        rpy="0 0 0" />
      <mass
        value="0.47584" />
      <inertia
        ixx="0.00040759"
        ixy="-1.3958E-10"
        ixz="-1.3527E-06"
        iyy="0.00040186"
        iyz="-1.5768E-10"
        izz="0.0003397" />
    </inertial>
    <visual>
      <origin
        xyz="0 0 0"
        rpy="0 0 0" />
      <geometry>
        <mesh
          filename="package://mars_rover/meshes/LiDAR.dae" />
      </geometry>
      <material
        name="">
        <color
          rgba="0.69804 0.69804 0.69804 1" />
      </material>
    </visual>
    <collision>
      <origin
        xyz="0 0 0"
        rpy="0 0 0" />
      <geometry>
        <mesh
          filename="package://mars_rover/meshes/LiDAR.dae" />
      </geometry>
    </collision>
  </link>
  <joint
    name="joint_LiDARSupport_LiDAR"
    type="fixed">
    <origin
      xyz="0.033455 0 0.056977"
      rpy="0 1.1345 0" />
    <parent
      link="LiDARSupport" />
    <child
      link="LiDAR" />
    <axis
      xyz="0 0 0" />
  </joint>
    
    <xacro:include filename="$(find mars_rover)/urdf/Sensors.xacro"/>
    <xacro:PandarQT link="${LidarName}" topic="${LidarDataTopicName}" hz="${LidarHz}" lasers="${LidarLasers}" samples="${LidarSamples}" visual="${LidarBeamVisual}"></xacro:PandarQT>
    <xacro:IMU link="${LidarName}" pitch="${0}" gaussianNoise="0.0"></xacro:IMU>
</robot>